2024-09-26 00:28:57,542 INFO    StreamThr :86048 [internal.py:wandb_internal():85] W&B internal server running at pid: 86048, started at: 2024-09-26 00:28:57.541937
2024-09-26 00:28:57,543 DEBUG   HandlerThread:86048 [handler.py:handle_request():158] handle_request: status
2024-09-26 00:28:57,544 INFO    WriterThread:86048 [datastore.py:open_for_write():87] open: /home/daniel/dev/kan-pref/pref_kan/notebooks/wandb/run-20240926_002857-ur7iftka/run-ur7iftka.wandb
2024-09-26 00:28:57,544 DEBUG   SenderThread:86048 [sender.py:send():391] send: header
2024-09-26 00:28:57,553 DEBUG   SenderThread:86048 [sender.py:send():391] send: run
2024-09-26 00:28:57,788 DEBUG   HandlerThread:86048 [handler.py:handle_request():158] handle_request: status_report
2024-09-26 00:28:57,824 ERROR   SenderThread:86048 [internal_api.py:execute():349] 404 response executing GraphQL.
2024-09-26 00:28:57,824 ERROR   SenderThread:86048 [internal_api.py:execute():350] {"errors":[{"message":"entity daniellsmarta-kth not found during upsertBucket","path":["upsertBucket"]}],"data":{"upsertBucket":null}}
2024-09-26 00:28:57,824 ERROR   SenderThread:86048 [sender.py:send_run():1021] It appears that you do not have permission to access the requested resource. Please reach out to the project owner to grant you access. If you have the correct permissions, verify that there are no issues with your networking setup.(Error 404: Not Found)
Traceback (most recent call last):
  File "/home/daniel/software/anaconda3/envs/kan/lib/python3.9/site-packages/wandb/sdk/lib/retry.py", line 131, in __call__
    result = self._call_fn(*args, **kwargs)
  File "/home/daniel/software/anaconda3/envs/kan/lib/python3.9/site-packages/wandb/sdk/internal/internal_api.py", line 345, in execute
    return self.client.execute(*args, **kwargs)  # type: ignore
  File "/home/daniel/software/anaconda3/envs/kan/lib/python3.9/site-packages/wandb/vendor/gql-0.2.0/wandb_gql/client.py", line 52, in execute
    result = self._get_result(document, *args, **kwargs)
  File "/home/daniel/software/anaconda3/envs/kan/lib/python3.9/site-packages/wandb/vendor/gql-0.2.0/wandb_gql/client.py", line 60, in _get_result
    return self.transport.execute(document, *args, **kwargs)
  File "/home/daniel/software/anaconda3/envs/kan/lib/python3.9/site-packages/wandb/sdk/lib/gql_request.py", line 59, in execute
    request.raise_for_status()
  File "/home/daniel/software/anaconda3/envs/kan/lib/python3.9/site-packages/requests/models.py", line 1024, in raise_for_status
    raise HTTPError(http_error_msg, response=self)
requests.exceptions.HTTPError: 404 Client Error: Not Found for url: https://api.wandb.ai/graphql

During handling of the above exception, another exception occurred:

Traceback (most recent call last):
  File "/home/daniel/software/anaconda3/envs/kan/lib/python3.9/site-packages/wandb/sdk/internal/sender.py", line 1019, in send_run
    server_run = self._init_run(run, config_value_dict)
  File "/home/daniel/software/anaconda3/envs/kan/lib/python3.9/site-packages/wandb/sdk/internal/sender.py", line 1091, in _init_run
    server_run, inserted, server_messages = self._api.upsert_run(
  File "/home/daniel/software/anaconda3/envs/kan/lib/python3.9/site-packages/wandb/apis/normalize.py", line 73, in wrapper
    raise err
  File "/home/daniel/software/anaconda3/envs/kan/lib/python3.9/site-packages/wandb/apis/normalize.py", line 41, in wrapper
    return func(*args, **kwargs)
  File "/home/daniel/software/anaconda3/envs/kan/lib/python3.9/site-packages/wandb/sdk/internal/internal_api.py", line 2224, in upsert_run
    response = self.gql(
  File "/home/daniel/software/anaconda3/envs/kan/lib/python3.9/site-packages/wandb/sdk/internal/internal_api.py", line 317, in gql
    ret = self._retry_gql(
  File "/home/daniel/software/anaconda3/envs/kan/lib/python3.9/site-packages/wandb/sdk/lib/retry.py", line 147, in __call__
    retry_timedelta_triggered = check_retry_fn(e)
  File "/home/daniel/software/anaconda3/envs/kan/lib/python3.9/site-packages/wandb/util.py", line 968, in check_retry_fn
    return fallback_retry_fn(e)
  File "/home/daniel/software/anaconda3/envs/kan/lib/python3.9/site-packages/wandb/util.py", line 910, in no_retry_auth
    raise CommError(
wandb.errors.CommError: It appears that you do not have permission to access the requested resource. Please reach out to the project owner to grant you access. If you have the correct permissions, verify that there are no issues with your networking setup.(Error 404: Not Found)
2024-09-26 00:29:02,289 DEBUG   HandlerThread:86048 [handler.py:handle_request():158] handle_request: status_report
2024-09-26 00:29:02,790 DEBUG   HandlerThread:86048 [handler.py:handle_request():158] handle_request: status_report
2024-09-26 00:29:02,827 DEBUG   HandlerThread:86048 [handler.py:handle_request():158] handle_request: status_report
2024-09-26 00:29:07,291 DEBUG   HandlerThread:86048 [handler.py:handle_request():158] handle_request: status_report
2024-09-26 00:29:07,792 DEBUG   HandlerThread:86048 [handler.py:handle_request():158] handle_request: status_report
2024-09-26 00:29:07,828 DEBUG   HandlerThread:86048 [handler.py:handle_request():158] handle_request: status_report
2024-09-26 00:29:12,292 DEBUG   HandlerThread:86048 [handler.py:handle_request():158] handle_request: status_report
2024-09-26 00:29:12,792 DEBUG   HandlerThread:86048 [handler.py:handle_request():158] handle_request: status_report
2024-09-26 00:29:12,829 DEBUG   HandlerThread:86048 [handler.py:handle_request():158] handle_request: status_report
2024-09-26 00:29:17,293 DEBUG   HandlerThread:86048 [handler.py:handle_request():158] handle_request: status_report
2024-09-26 00:29:17,793 DEBUG   HandlerThread:86048 [handler.py:handle_request():158] handle_request: status_report
2024-09-26 00:29:17,830 DEBUG   HandlerThread:86048 [handler.py:handle_request():158] handle_request: status_report
2024-09-26 00:29:22,293 DEBUG   HandlerThread:86048 [handler.py:handle_request():158] handle_request: status_report
2024-09-26 00:29:22,794 DEBUG   HandlerThread:86048 [handler.py:handle_request():158] handle_request: status_report
2024-09-26 00:29:22,831 DEBUG   HandlerThread:86048 [handler.py:handle_request():158] handle_request: status_report
2024-09-26 00:29:27,294 DEBUG   HandlerThread:86048 [handler.py:handle_request():158] handle_request: status_report
2024-09-26 00:29:27,794 DEBUG   HandlerThread:86048 [handler.py:handle_request():158] handle_request: status_report
2024-09-26 00:29:27,831 DEBUG   HandlerThread:86048 [handler.py:handle_request():158] handle_request: status_report
2024-09-26 00:29:28,312 INFO    StreamThr :86048 [internal.py:wandb_internal():85] W&B internal server running at pid: 86048, started at: 2024-09-26 00:29:28.312095
2024-09-26 00:29:28,314 DEBUG   HandlerThread:86048 [handler.py:handle_request():158] handle_request: status
2024-09-26 00:29:28,314 INFO    WriterThread:86048 [datastore.py:open_for_write():87] open: /home/daniel/dev/kan-pref/pref_kan/notebooks/wandb/run-20240926_002928-5qm1w0yu/run-5qm1w0yu.wandb
2024-09-26 00:29:28,315 DEBUG   SenderThread:86048 [sender.py:send():391] send: header
2024-09-26 00:29:28,324 DEBUG   SenderThread:86048 [sender.py:send():391] send: run
2024-09-26 00:29:28,598 ERROR   SenderThread:86048 [internal_api.py:execute():349] 404 response executing GraphQL.
2024-09-26 00:29:28,598 ERROR   SenderThread:86048 [internal_api.py:execute():350] {"errors":[{"message":"entity daniellsmarta-kth not found during upsertBucket","path":["upsertBucket"]}],"data":{"upsertBucket":null}}
2024-09-26 00:29:28,599 ERROR   SenderThread:86048 [sender.py:send_run():1021] It appears that you do not have permission to access the requested resource. Please reach out to the project owner to grant you access. If you have the correct permissions, verify that there are no issues with your networking setup.(Error 404: Not Found)
Traceback (most recent call last):
  File "/home/daniel/software/anaconda3/envs/kan/lib/python3.9/site-packages/wandb/sdk/lib/retry.py", line 131, in __call__
    result = self._call_fn(*args, **kwargs)
  File "/home/daniel/software/anaconda3/envs/kan/lib/python3.9/site-packages/wandb/sdk/internal/internal_api.py", line 345, in execute
    return self.client.execute(*args, **kwargs)  # type: ignore
  File "/home/daniel/software/anaconda3/envs/kan/lib/python3.9/site-packages/wandb/vendor/gql-0.2.0/wandb_gql/client.py", line 52, in execute
    result = self._get_result(document, *args, **kwargs)
  File "/home/daniel/software/anaconda3/envs/kan/lib/python3.9/site-packages/wandb/vendor/gql-0.2.0/wandb_gql/client.py", line 60, in _get_result
    return self.transport.execute(document, *args, **kwargs)
  File "/home/daniel/software/anaconda3/envs/kan/lib/python3.9/site-packages/wandb/sdk/lib/gql_request.py", line 59, in execute
    request.raise_for_status()
  File "/home/daniel/software/anaconda3/envs/kan/lib/python3.9/site-packages/requests/models.py", line 1024, in raise_for_status
    raise HTTPError(http_error_msg, response=self)
requests.exceptions.HTTPError: 404 Client Error: Not Found for url: https://api.wandb.ai/graphql

During handling of the above exception, another exception occurred:

Traceback (most recent call last):
  File "/home/daniel/software/anaconda3/envs/kan/lib/python3.9/site-packages/wandb/sdk/internal/sender.py", line 1019, in send_run
    server_run = self._init_run(run, config_value_dict)
  File "/home/daniel/software/anaconda3/envs/kan/lib/python3.9/site-packages/wandb/sdk/internal/sender.py", line 1091, in _init_run
    server_run, inserted, server_messages = self._api.upsert_run(
  File "/home/daniel/software/anaconda3/envs/kan/lib/python3.9/site-packages/wandb/apis/normalize.py", line 73, in wrapper
    raise err
  File "/home/daniel/software/anaconda3/envs/kan/lib/python3.9/site-packages/wandb/apis/normalize.py", line 41, in wrapper
    return func(*args, **kwargs)
  File "/home/daniel/software/anaconda3/envs/kan/lib/python3.9/site-packages/wandb/sdk/internal/internal_api.py", line 2224, in upsert_run
    response = self.gql(
  File "/home/daniel/software/anaconda3/envs/kan/lib/python3.9/site-packages/wandb/sdk/internal/internal_api.py", line 317, in gql
    ret = self._retry_gql(
  File "/home/daniel/software/anaconda3/envs/kan/lib/python3.9/site-packages/wandb/sdk/lib/retry.py", line 147, in __call__
    retry_timedelta_triggered = check_retry_fn(e)
  File "/home/daniel/software/anaconda3/envs/kan/lib/python3.9/site-packages/wandb/util.py", line 968, in check_retry_fn
    return fallback_retry_fn(e)
  File "/home/daniel/software/anaconda3/envs/kan/lib/python3.9/site-packages/wandb/util.py", line 910, in no_retry_auth
    raise CommError(
wandb.errors.CommError: It appears that you do not have permission to access the requested resource. Please reach out to the project owner to grant you access. If you have the correct permissions, verify that there are no issues with your networking setup.(Error 404: Not Found)
2024-09-26 00:29:32,295 DEBUG   HandlerThread:86048 [handler.py:handle_request():158] handle_request: status_report
2024-09-26 00:29:32,795 DEBUG   HandlerThread:86048 [handler.py:handle_request():158] handle_request: status_report
2024-09-26 00:29:32,832 DEBUG   HandlerThread:86048 [handler.py:handle_request():158] handle_request: status_report
2024-09-26 00:29:33,324 DEBUG   HandlerThread:86048 [handler.py:handle_request():158] handle_request: keepalive
2024-09-26 00:29:33,600 DEBUG   HandlerThread:86048 [handler.py:handle_request():158] handle_request: status_report
2024-09-26 00:29:37,295 DEBUG   HandlerThread:86048 [handler.py:handle_request():158] handle_request: status_report
2024-09-26 00:29:37,795 DEBUG   HandlerThread:86048 [handler.py:handle_request():158] handle_request: status_report
2024-09-26 00:29:37,832 DEBUG   HandlerThread:86048 [handler.py:handle_request():158] handle_request: status_report
2024-09-26 00:29:38,325 DEBUG   HandlerThread:86048 [handler.py:handle_request():158] handle_request: keepalive
2024-09-26 00:29:38,600 DEBUG   HandlerThread:86048 [handler.py:handle_request():158] handle_request: status_report
